data/sample.csv
# ts_ns,MsgType,Side,OrderId,Price,Qty
1693526400000000000,NewLimit,Buy,1,100050,10
1693526400001000000,NewLimit,Sell,2,100060,5
1693526400002000000,NewMarket,Buy,3,0,7
1693526400003000000,Cancel,Sell,2,0,0
1693526400004000000,NewLimit,Buy,4,100055,15
1693526400005000000,NewLimit,Sell,5,100055,8
1693526400006000000,NewLimit,Sell,6,100060,12
1693526400007000000,NewLimit,Buy,7,100065,20
1693526400008000000,Cancel,Buy,4,0,0
1693526400009000000,NewMarket,Sell,8,0,5
